<robot name="thor">
    <link name="base">
      <visual>
	<origin xyz="0 0 0" rpy="0 0 0"/>
	<geometry>
	  <mesh filename="package://thor_arm_description/meshes/base.stl" scale="0.001 0.001 0.001" />
	</geometry>
      </visual>
    </link>

    <joint name="art1_yaw" type="revolute">
      <origin xyz="0 0 0.104" rpy="0 0 0"/>
      <axis xyz="0 0 1"/>
      <parent link="base"/>
      <child link="art1"/>
      <limit lower="-3.1415" upper="3.1415" effort="4" velocity="1" />
    </joint>

    <link name="art1">
      <visual>
	<origin xyz="0 0 0" rpy="0 0 0" />
	<geometry>
	  <mesh filename="package://thor_arm_description/meshes/art1.stl" scale="0.001 0.001 0.001" />
	</geometry>
      </visual>
    </link>

    <joint name="art2_pitch" type="revolute">
        <origin xyz="0 -0.0318752 0.0974304" rpy="1.5707963267948966 -1.5707963267948966 0"/>
	<axis xyz="0 0 1"/>
	<parent link="art1"/>
        <child link="art2"/>
	<limit lower="-1.5707963267948966" upper="1.5707963267948966" effort="4" velocity="1" />
    </joint>

    <link name="art2">
      <visual>
	<origin xyz="0 0 0" rpy="0 0 0" />
	<geometry>
	  <mesh filename="package://thor_arm_description/meshes/art2.stl" scale="0.001 0.001 0.001" />
	</geometry>
      </visual>
    </link>

    <joint name="art3_pitch" type="revolute">
        <origin xyz="0.160 0 0" rpy="0 0 0"/>
	<axis xyz="0 0 1"/>
	<parent link="art2"/>
        <child link="art3"/>
	<limit lower="-1.5707963267948966" upper="1.5707963267948966" effort="4" velocity="1" />
    </joint>

    <link name="art3">
      <visual>
	<origin xyz="0 0 0" rpy="0 0 0" />
	<geometry>
	  <mesh filename="package://thor_arm_description/meshes/art3.stl" scale="0.001 0.001 0.001" />
	</geometry>
      </visual>
    </link>

    <joint name="art4_roll" type="revolute">
        <origin xyz="0.0885 0 -0.035" rpy="0 1.5707963267948966 0"/>
	<axis xyz="0 0 1"/>
	<parent link="art3"/>
        <child link="art4"/>
	<limit lower="-1.5707963267948966" upper="1.5707963267948966" effort="4" velocity="1" />
    </joint>

    <link name="art4">
      <visual>
	<origin xyz="0 0 0" rpy="0 0 0" />
	<geometry>
	  <mesh filename="package://thor_arm_description/meshes/art4.stl" scale="0.001 0.001 0.001" />
	</geometry>
      </visual>
    </link>

</robot>
